<?xml version="1.0" ?>
<sdf version='1.7'>
  <model name='my_agv_super'>
    <link name='base_footprint'>
      <inertial>
        <pose>0.000188 0 0.060568 0 -0 0</pose>
        <mass>40.114</mass>
        <inertia>
          <ixx>0.224444</ixx>
          <ixy>5.35963e-17</ixy>
          <ixz>-0.00150052</ixz>
          <iyy>0.41414</iyy>
          <iyz>2.59038e-32</iyz>
          <izz>0.543363</izz>
        </inertia>
      </inertial>
      <collision name='base_footprint_fixed_joint_lump__base_link_collision'>
        <pose>0 0 0.06 0 -0 0</pose>
        <geometry>
          <box>
            <size>0.33115 0.23 0.113</size>
          </box>
        </geometry>
        <surface>
          <contact>
            <ode/>
          </contact>
          <friction>
            <ode/>
          </friction>
        </surface>
      </collision>
      <collision name='base_footprint_fixed_joint_lump__lidar_link_collision_1'>
        <pose>0.066 0 0.26 0 -0 0</pose>
        <geometry>
          <cylinder>
            <length>0.08</length>
            <radius>0.0508</radius>
          </cylinder>
        </geometry>
      </collision>
      <visual name='base_footprint_fixed_joint_lump__base_link_visual'>
        <pose>0 0 0.01 0 -0 0</pose>
        <geometry>
          <mesh>
            <scale>1 1 1</scale>
            <uri>model://my_agv_super/meshes/myagv_all.dae</uri>
          </mesh>
        </geometry>
        <material>
          <script>
            <name>Gazebo/Red</name>
            <uri>file://media/materials/scripts/gazebo.material</uri>
          </script>
        </material>
      </visual>
      <visual name='base_footprint_fixed_joint_lump__lidar_link_visual_1'>
        <pose>0.066 0 0.26 0 -0 0</pose>
        <geometry>
          <cylinder>
            <length>0.05</length>
            <radius>0.04</radius>
          </cylinder>
        </geometry>
      </visual>
    </link>
    <joint name='left_wheel_back_joint' type='revolute'>
      <pose relative_to='base_footprint'>-0.106 0.115 0.05 0 -0 0</pose>
      <parent>base_footprint</parent>
      <child>left_wheel_back_link</child>
      <axis>
        <xyz>0 1 0</xyz>
        <limit>
          <lower>-3.1415</lower>
          <upper>3.1415</upper>
          <effort>30</effort>
          <velocity>5</velocity>
        </limit>
        <dynamics>
          <spring_reference>0</spring_reference>
          <spring_stiffness>0</spring_stiffness>
        </dynamics>
      </axis>
    </joint>
    <link name='left_wheel_back_link'>
      <pose relative_to='left_wheel_back_joint'>0 0 0 0 -0 0</pose>
      <inertial>
        <pose>0 0 0 1.5708 -0 0</pose>
        <mass>110.5</mass>
        <inertia>
          <ixx>0.102212</ixx>
          <ixy>0</ixy>
          <ixz>0</ixz>
          <iyy>0.102212</iyy>
          <iyz>0</iyz>
          <izz>0.138125</izz>
        </inertia>
      </inertial>
      <collision name='left_wheel_back_link_collision'>
        <pose>0 0 0 1.5708 -0 0</pose>
        <geometry>
          <cylinder>
            <length>0.06</length>
            <radius>0.05</radius>
          </cylinder>
        </geometry>
      </collision>
      <visual name='left_wheel_back_link_visual'>
        <pose>0 0 0 1.5708 -0 0</pose>
        <geometry>
          <cylinder>
            <length>0.06</length>
            <radius>0.05</radius>
          </cylinder>
        </geometry>
      </visual>
    </link>
    <joint name='left_wheel_front_joint' type='revolute'>
      <pose relative_to='base_footprint'>0.106 0.115 0.05 0 -0 0</pose>
      <parent>base_footprint</parent>
      <child>left_wheel_front_link</child>
      <axis>
        <xyz>0 1 0</xyz>
        <limit>
          <lower>-3.1415</lower>
          <upper>3.1415</upper>
          <effort>30</effort>
          <velocity>5</velocity>
        </limit>
        <dynamics>
          <spring_reference>0</spring_reference>
          <spring_stiffness>0</spring_stiffness>
        </dynamics>
      </axis>
    </joint>
    <link name='left_wheel_front_link'>
      <pose relative_to='left_wheel_front_joint'>0 0 0 0 -0 0</pose>
      <inertial>
        <pose>0 0 0 1.5708 -0 0</pose>
        <mass>110.5</mass>
        <inertia>
          <ixx>0.102212</ixx>
          <ixy>0</ixy>
          <ixz>0</ixz>
          <iyy>0.102212</iyy>
          <iyz>0</iyz>
          <izz>0.138125</izz>
        </inertia>
      </inertial>
      <collision name='left_wheel_front_link_collision'>
        <pose>0 0 0 1.5708 -0 0</pose>
        <geometry>
          <cylinder>
            <length>0.06</length>
            <radius>0.05</radius>
          </cylinder>
        </geometry>
      </collision>
      <visual name='left_wheel_front_link_visual'>
        <pose>0 0 0 1.5708 -0 0</pose>
        <geometry>
          <cylinder>
            <length>0.06</length>
            <radius>0.05</radius>
          </cylinder>
        </geometry>
      </visual>
    </link>
    <joint name='right_wheel_back_joint' type='revolute'>
      <pose relative_to='base_footprint'>-0.106 -0.115 0.05 0 -0 0</pose>
      <parent>base_footprint</parent>
      <child>right_wheel_back_link</child>
      <axis>
        <xyz>0 1 0</xyz>
        <limit>
          <lower>-3.1415</lower>
          <upper>3.1415</upper>
          <effort>30</effort>
          <velocity>5</velocity>
        </limit>
        <dynamics>
          <spring_reference>0</spring_reference>
          <spring_stiffness>0</spring_stiffness>
        </dynamics>
      </axis>
    </joint>
    <link name='right_wheel_back_link'>
      <pose relative_to='right_wheel_back_joint'>0 0 0 0 -0 0</pose>
      <inertial>
        <pose>0 0 0 1.5708 -0 0</pose>
        <mass>110.5</mass>
        <inertia>
          <ixx>0.102212</ixx>
          <ixy>0</ixy>
          <ixz>0</ixz>
          <iyy>0.102212</iyy>
          <iyz>0</iyz>
          <izz>0.138125</izz>
        </inertia>
      </inertial>
      <collision name='right_wheel_back_link_collision'>
        <pose>0 0 0 1.5708 -0 0</pose>
        <geometry>
          <cylinder>
            <length>0.06</length>
            <radius>0.05</radius>
          </cylinder>
        </geometry>
      </collision>
      <visual name='right_wheel_back_link_visual'>
        <pose>0 0 0 1.5708 -0 0</pose>
        <geometry>
          <cylinder>
            <length>0.06</length>
            <radius>0.05</radius>
          </cylinder>
        </geometry>
      </visual>
    </link>
    <joint name='right_wheel_front_joint' type='revolute'>
      <pose relative_to='base_footprint'>0.106 -0.115 0.05 0 -0 0</pose>
      <parent>base_footprint</parent>
      <child>right_wheel_front_link</child>
      <axis>
        <xyz>0 1 0</xyz>
        <limit>
          <lower>-3.1415</lower>
          <upper>3.1415</upper>
          <effort>30</effort>
          <velocity>5</velocity>
        </limit>
        <dynamics>
          <spring_reference>0</spring_reference>
          <spring_stiffness>0</spring_stiffness>
        </dynamics>
      </axis>
    </joint>
    <link name='right_wheel_front_link'>
      <pose relative_to='right_wheel_front_joint'>0 0 0 0 -0 0</pose>
      <inertial>
        <pose>0 0 0 1.5708 -0 0</pose>
        <mass>110.5</mass>
        <inertia>
          <ixx>0.102212</ixx>
          <ixy>0</ixy>
          <ixz>0</ixz>
          <iyy>0.102212</iyy>
          <iyz>0</iyz>
          <izz>0.138125</izz>
        </inertia>
      </inertial>
      <collision name='right_wheel_front_link_collision'>
        <pose>0 0 0 1.5708 -0 0</pose>
        <geometry>
          <cylinder>
            <length>0.06</length>
            <radius>0.05</radius>
          </cylinder>
        </geometry>
      </collision>
      <visual name='right_wheel_front_link_visual'>
        <pose>0 0 0 1.5708 -0 0</pose>
        <geometry>
          <cylinder>
            <length>0.06</length>
            <radius>0.05</radius>
          </cylinder>
        </geometry>
      </visual>
    </link>
    
    
    
    
    

<!-- ****************************** LIDAR *****************************    -->
    <!-- Add LIDAR link here -->
    <link name="lidar_link">
      <pose>0.066 0 0.1 0 0 0</pose> <!-- Adjust the pose to position the lidar correctly on the roof -->
      
      <inertial>
        <pose>0 0 0 0 0 0</pose>
        <inertia>
          <ixx>0.001</ixx>
          <ixy>0.000</ixy>
          <ixz>0.000</ixz>
          <iyy>0.001</iyy>
          <iyz>0.000</iyz>
          <izz>0.001</izz>
        </inertia>
        <mass>0.114</mass>
      </inertial>

      <collision name="lidar_collision">
        <pose>0 0 0 0 0 0</pose>
        <geometry>
          <cylinder>
            <radius>0.04</radius>
            <length>0.05</length>
          </cylinder>
        </geometry>
      </collision>

      <visual name="lidar_visual">
        <pose>0 0 0 0 0 0</pose>
        <geometry>
          <cylinder>
            <radius>0.04</radius>
            <length>0.05</length>
          </cylinder>
        </geometry>
        <material>
          <ambient>0.0 0.0 0.0 1.0</ambient>
          <diffuse>0.0 0.0 0.0 1.0</diffuse>
          <specular>0.0 0.0 0.0 1.0</specular>
          <emissive>0.0 0.0 0.0 1.0</emissive>
        </material>
      </visual>

      <sensor name="lidar" type="ray">
        <pose>0 0 0 0 0 0</pose>
        <always_on>true</always_on>
        <visualize>true</visualize>
        <update_rate>5</update_rate>
        <ray>
          <scan>
            <horizontal>
              <samples>360</samples>
              <resolution>1.00000</resolution>
              <min_angle>-2.14</min_angle>
              <max_angle>2.14</max_angle>
            </horizontal>
          </scan>
          <range>
            <min>0.350000</min>
            <max>25</max>
            <resolution>0.015000</resolution>
          </range>
          <noise>
            <type>gaussian</type>
            <mean>0.0</mean>
            <stddev>0.01</stddev>
          </noise>
        </ray>
        <plugin name="scan" filename="libgazebo_ros_ray_sensor.so">
          <ros>
            <remapping>~/out:=scan</remapping>
          </ros>
          <output_type>sensor_msgs/LaserScan</output_type>
          <frame_name>lidar_link</frame_name>
        </plugin>
      </sensor>
    </link>

    <joint name="lidar_joint" type="fixed">
      <pose>0 0 0 0 0 0</pose>
      <parent>base_link</parent>
      <child>lidar_link</child>
    </joint>
    
    
    
   <!-- *********************** IMU SENSOR SETUP **************************  -->
  <link name="imu_link">
   <pose>-0.10 0 0.05 0 0 0</pose>
    <gravity>true</gravity>
    <sensor name="bmb_imu" type="imu">
      <always_on>true</always_on>
      <update_rate>100</update_rate>
      <visualize>true</visualize>
      <imu>
        <orientation>
          <x>
            <noise type="gaussian">
              <mean>0.0</mean>
              <stddev>2e-3</stddev>
            </noise>
          </x>
          <y>
            <noise type="gaussian">
              <mean>0.0</mean>
              <stddev>2e-3</stddev>
            </noise>
          </y>
          <z>
            <noise type="gaussian">
              <mean>0.0</mean>
              <stddev>2e-3</stddev>
            </noise>
          </z>
        </orientation>
        <angular_velocity>
          <x>
            <noise type="gaussian">
              <mean>0.0</mean>
              <stddev>2e-4</stddev>
            </noise>
          </x>
          <y>
            <noise type="gaussian">
              <mean>0.0</mean>
              <stddev>2e-4</stddev>
            </noise>
          </y>
          <z>
            <noise type="gaussian">
              <mean>0.0</mean>
              <stddev>2e-4</stddev>
            </noise>
          </z>
        </angular_velocity>
        <linear_acceleration>
          <x>
            <noise type="gaussian">
              <mean>0.0</mean>
              <stddev>1.7e-2</stddev>
            </noise>
          </x>
          <y>
            <noise type="gaussian">
              <mean>0.0</mean>
              <stddev>1.7e-2</stddev>
            </noise>
          </y>
          <z>
            <noise type="gaussian">
              <mean>0.0</mean>
              <stddev>1.7e-2</stddev>
            </noise>
          </z>
        </linear_acceleration>
      </imu>
      <plugin name="myagv_imu" filename="libgazebo_ros_imu_sensor.so">
        <initial_orientation_as_reference>false</initial_orientation_as_reference>
        <frame_name>imu_link</frame_name>
        <ros>
          <namespace>/imu</namespace>
          <remapping>~/out:=data</remapping>
        </ros>
      </plugin>
    </sensor>
  </link>

  <!-- *********************** GPS SETUP *********************************  -->
  <link name="gps_link">
   <pose>0.0 0.0 0.2 0.0 0.0 0.0</pose> 
    <sensor name="bmb_gps" type="gps">
      <always_on>true</always_on>
      <update_rate>10.0</update_rate>
      <gps>
        <position_sensing>
          <horizontal>
            <noise type="gaussian">
              <mean>0.0</mean>
              <stddev>1e-2</stddev>
            </noise>
          </horizontal>
          <vertical>
            <noise type="gaussian">
              <mean>0.0</mean>
              <stddev>1</stddev>
            </noise>
          </vertical>
        </position_sensing>
      </gps>
      <plugin name="myagv_gps" filename="libgazebo_ros_gps_sensor.so">
        <ros>
          <remapping>~/out:=gps/fix</remapping>
        </ros>
      </plugin>
    </sensor>
  </link>

<!--
<plugin name="skid_steer_drive" filename="libgazebo_ros_diff_drive.so">

  <ros>
    <namespace> </namespace>
  </ros>
  <num_wheel_pairs>2</num_wheel_pairs>
   <left_joint>left_wheel_front_joint</left_joint>
    <right_joint>right_wheel_front_joint</right_joint>
    <left_joint>left_wheel_back_joint</left_joint>
    <right_joint>right_wheel_back_joint</right_joint> 
  <wheel_separation>0.26</wheel_separation>
  <wheel_separation>0.26</wheel_separation>
  <wheel_diameter>0.4</wheel_diameter>
  <wheel_diameter>0.4</wheel_diameter>
  <max_wheel_torque>1000</max_wheel_torque>
  <max_wheel_acceleration>20.0</max_wheel_acceleration>
  <publish_odom>true</publish_odom>
   <publish_odom_tf>true</publish_odom_tf>
   <publish_wheel_tf>true</publish_wheel_tf>
   <odometry_frame>odom</odometry_frame>
   <robot_base_frame>base_footprint</robot_base_frame>
   <ros>
      <remapping>odom:=wheel/odometry</remapping>
    </ros>
 
</plugin>


-->
<plugin name="omni_steering" filename="libgazebo_ros_planar_move.so">
	<commandTopic>cmd_vel</commandTopic>
	<odometryTopic>odom</odometryTopic>
	<odometryFrame>odom</odometryFrame>
	<odometryRate>50.0</odometryRate>
	<robotBaseFrame>base_footprint</robotBaseFrame>
	<publishTF>true</publishTF>
	<ros>
      <remapping>odom:=wheel/odometry</remapping>
    </ros>
</plugin>

<plugin name="my_agv_joint_state" filename="libgazebo_ros_joint_state_publisher.so">
 
    <update_rate>30</update_rate>
    <joint_name>left_wheel_front_joint</joint_name>
    <joint_name>right_wheel_front_joint</joint_name>
    <joint_name>left_wheel_back_joint</joint_name>
    <joint_name>right_wheel_back_joint</joint_name>
       <ros>
      <remapping>~/out:=joint_states</remapping>
    </ros>
  </plugin>   
  </model>
</sdf>
