<?xml version="1.0" ?>
<!-- =================================================================================== -->
<!-- |    This document was autogenerated by xacro from myagv.urdf                     | -->
<!-- |    EDITING THIS FILE BY HAND IS NOT RECOMMENDED                                 | -->
<!-- =================================================================================== -->
<robot name="my_agv_super">
  <!-- ****************** ROBOT BASE FOOTPRINT ***************************  -->
  <!-- Define the center of the main robot chassis projected on the ground -->
  <link name="base_footprint"/>
  <!-- The base footprint of the robot is located underneath the chassis -->
  <joint name="base_joint" type="fixed">
    <parent link="base_footprint"/>
    <child link="base_link"/>
    <origin rpy="0 0 0" xyz="0.0 0.0 0.060000000000000005"/>
  </joint>
  <!-- ********************** ROBOT BASE *********************************  -->
  <link name="base_link">
    <visual>
      <geometry>
        <mesh filename="package://my_agv_super/meshes/myagv_all.dae" scale="1 1 1"/>
      </geometry>
      <origin rpy="0.0 0.0 0.0" xyz="0.0 0.0 -0.05"/>
      <material name="black">
        <color rgba="0.7 0.5 0.0 0.5"/>
      </material>
    </visual>
    <!--
     <visual>
      <origin xyz="0 0 -0.05" rpy="1.5707963267949 0 3.141592654"/>
      <geometry>
        <mesh filename="package://basic_mobile_robot/meshes/myagv_all.dae" />
      </geometry>
      <material name="Red">
        <color rgba="${255/255} ${0/255} ${0/255} 1.0"/>
      </material>
    </visual>
 -->
    <collision>
      <geometry>
        <box size="0.33115 0.23 0.113"/>
      </geometry>
    </collision>
    <inertial>
      <origin rpy="1.5707963267948966 0 1.5707963267948966" xyz="0 0 0"/>
      <mass value="40.0"/>
      <inertia ixx="0.4080977416666667" ixy="0.0" ixz="0.0" iyy="0.5418677416666667" iyz="0.0" izz="0.21889666666666668"/>
    </inertial>
  </link>
  <gazebo reference="base_link">
    <material>Gazebo/Red</material>
  </gazebo>
  <!-- *********************** DRIVE WHEELS ******************************  -->
  <link name="left_wheel_back_link">
    <visual>
      <origin rpy="1.5707963267949 0 0" xyz="0 0 0"/>
      <geometry>
        <cylinder length="0.06" radius="0.05"/>
      </geometry>
      <material name="White">
        <color rgba="1.0 1.0 1.0 1.0"/>
      </material>
    </visual>
    <collision>
      <origin rpy="1.5707963267948966 0 0" xyz="0 0 0"/>
      <geometry>
        <cylinder length="0.06" radius="0.05"/>
      </geometry>
    </collision>
    <inertial>
      <origin rpy="1.5707963267948966 0 0" xyz="0 0 0"/>
      <mass value="110.5"/>
      <inertia ixx="0.10221250000000003" ixy="0" ixz="0" iyy="0.10221250000000003" iyz="0" izz="0.13812500000000003"/>
    </inertial>
  </link>
  <!-- Connect the wheels to the base_link at the appropriate location, and 
         define a continuous joint to allow the wheels to freely rotate about
         an axis -->
  <joint name="left_wheel_back_joint" type="revolute">
    <parent link="base_link"/>
    <child link="left_wheel_back_link"/>
    <origin rpy="0 0 0" xyz="-0.106 0.115 -0.01"/>
    <limit effort="30" lower="-3.1415" upper="3.1415" velocity="5.0"/>
    <axis xyz="0 1 0"/>
  </joint>
  <link name="right_wheel_back_link">
    <visual>
      <origin rpy="1.5707963267949 0 0" xyz="0 0 0"/>
      <geometry>
        <cylinder length="0.06" radius="0.05"/>
      </geometry>
      <material name="White">
        <color rgba="1.0 1.0 1.0 1.0"/>
      </material>
    </visual>
    <collision>
      <origin rpy="1.5707963267948966 0 0" xyz="0 0 0"/>
      <geometry>
        <cylinder length="0.06" radius="0.05"/>
      </geometry>
    </collision>
    <inertial>
      <origin rpy="1.5707963267948966 0 0" xyz="0 0 0"/>
      <mass value="110.5"/>
      <inertia ixx="0.10221250000000003" ixy="0" ixz="0" iyy="0.10221250000000003" iyz="0" izz="0.13812500000000003"/>
    </inertial>
  </link>
  <!-- Connect the wheels to the base_link at the appropriate location, and 
         define a continuous joint to allow the wheels to freely rotate about
         an axis -->
  <joint name="right_wheel_back_joint" type="revolute">
    <parent link="base_link"/>
    <child link="right_wheel_back_link"/>
    <origin rpy="0 0 0" xyz="-0.106 -0.115 -0.01"/>
    <limit effort="30" lower="-3.1415" upper="3.1415" velocity="5.0"/>
    <axis xyz="0 1 0"/>
  </joint>
  <link name="left_wheel_front_link">
    <visual>
      <origin rpy="1.5707963267949 0 0" xyz="0 0 0"/>
      <geometry>
        <cylinder length="0.06" radius="0.05"/>
      </geometry>
      <material name="White">
        <color rgba="1.0 1.0 1.0 1.0"/>
      </material>
    </visual>
    <collision>
      <origin rpy="1.5707963267948966 0 0" xyz="0 0 0"/>
      <geometry>
        <cylinder length="0.06" radius="0.05"/>
      </geometry>
    </collision>
    <inertial>
      <origin rpy="1.5707963267948966 0 0" xyz="0 0 0"/>
      <mass value="110.5"/>
      <inertia ixx="0.10221250000000003" ixy="0" ixz="0" iyy="0.10221250000000003" iyz="0" izz="0.13812500000000003"/>
    </inertial>
  </link>
  <!-- Connect the wheels to the base_link at the appropriate location, and 
         define a continuous joint to allow the wheels to freely rotate about
         an axis -->
  <joint name="left_wheel_front_joint" type="revolute">
    <parent link="base_link"/>
    <child link="left_wheel_front_link"/>
    <origin rpy="0 0 0" xyz="0.106 0.115 -0.01"/>
    <limit effort="30" lower="-3.1415" upper="3.1415" velocity="5.0"/>
    <axis xyz="0 1 0"/>
  </joint>
  <link name="right_wheel_front_link">
    <visual>
      <origin rpy="1.5707963267949 0 0" xyz="0 0 0"/>
      <geometry>
        <cylinder length="0.06" radius="0.05"/>
      </geometry>
      <material name="White">
        <color rgba="1.0 1.0 1.0 1.0"/>
      </material>
    </visual>
    <collision>
      <origin rpy="1.5707963267948966 0 0" xyz="0 0 0"/>
      <geometry>
        <cylinder length="0.06" radius="0.05"/>
      </geometry>
    </collision>
    <inertial>
      <origin rpy="1.5707963267948966 0 0" xyz="0 0 0"/>
      <mass value="110.5"/>
      <inertia ixx="0.10221250000000003" ixy="0" ixz="0" iyy="0.10221250000000003" iyz="0" izz="0.13812500000000003"/>
    </inertial>
  </link>
  <!-- Connect the wheels to the base_link at the appropriate location, and 
         define a continuous joint to allow the wheels to freely rotate about
         an axis -->
  <joint name="right_wheel_front_joint" type="revolute">
    <parent link="base_link"/>
    <child link="right_wheel_front_link"/>
    <origin rpy="0 0 0" xyz="0.106 -0.115 -0.01"/>
    <limit effort="30" lower="-3.1415" upper="3.1415" velocity="5.0"/>
    <axis xyz="0 1 0"/>
  </joint>
  <!-- *********************** CASTER WHEEL ******************************  -->
  <!-- We add a caster wheel. It will be modeled as sphere.
       We define the wheel’s geometry, material and the joint to connect it to 
       base_link at the appropriate location. 
  <link name="front_caster">
    <visual>
      <geometry>
        <sphere radius="${(wheel_radius+wheel_zoff-(base_height/2))}"/>
      </geometry>
      <material name="White">
        <color rgba="${255/255} ${255/255} ${255/255} 1.0"/>
      </material>
    </visual>
    <collision>
      <origin xyz="0 0 0" rpy="0 0 0"/>
      <geometry>
        <sphere radius="${(wheel_radius+wheel_zoff-(base_height/2))}"/>
      </geometry>
    </collision>
    <xacro:sphere_inertia m="10.05" r="${(wheel_radius+wheel_zoff-(base_height/2))}"/>
  </link>

  <gazebo reference="front_caster">
    <mu1>0.01</mu1>
    <mu2>0.01</mu2>
    <material>Gazebo/White</material>
  </gazebo>

  <joint name="caster_joint" type="fixed">
    <parent link="base_link"/>
    <child link="front_caster"/>
    <origin xyz="${caster_xoff} 0.0 ${-(base_height/2)}" rpy="0 0 0"/>
  </joint>
  -->
  <!-- *********************** Lidar SETUP *********************************  -->
  <!-- Each sensor must be attached to a link.                              -->
  <joint name="lidar_joint" type="fixed">
    <parent link="base_link"/>
    <child link="lidar_link"/>
    <origin rpy="0 0 0" xyz="0.066 0 0.2"/>
  </joint>
  <link name="lidar_link">
    <collision>
      <origin rpy="0 0 0" xyz="0 0 0"/>
      <geometry>
        <cylinder length="0.08" radius="0.0508"/>
      </geometry>
    </collision>
    <visual>
      <origin rpy="0 0 0" xyz="0 0 0"/>
      <geometry>
        <cylinder length="0.05" radius="0.04"/>
      </geometry>
      <material name="Black">
        <color rgba="0.0 0.0 0.0 1.0"/>
      </material>
    </visual>
    <inertial>
      <mass value="0.114"/>
      <origin rpy="0 0 0" xyz="0 0 0"/>
      <inertia ixx="0.001" ixy="0" ixz="0" iyy="0.001" iyz="0" izz="0.001"/>
    </inertial>
  </link>
  <!-- *********************** IMU SETUP *********************************  -->
  <!-- Each sensor must be attached to a link.                              -->
  <joint name="imu_joint" type="fixed">
    <parent link="base_link"/>
    <child link="imu_link"/>
    <origin rpy="0 0 0" xyz="-0.10 0 0.05"/>
  </joint>
  <link name="imu_link"/>
  <!-- *********************** GPS SETUP **********************************  -->
  <joint name="gps_joint" type="fixed">
    <parent link="base_link"/>
    <child link="gps_link"/>
    <origin rpy="0 0 0" xyz="0.10 0 0.05"/>
  </joint>
  <link name="gps_link"/>
</robot>
